<robot name="test_robot">

  <!-- Base Link -->
  <link name="base_link">
    <visual>
      <geometry>
        <box size="0.14 0.07 0.05"/>
      </geometry>
      <origin rpy="0 0 0" xyz="0 0 0.045"/>
      <material name="white">
        <color rgba="1 1 1 1"/>
      </material>
    </visual>
    <collision>
      <geometry>
        <box size="0.14 0.07 0.05"/>
      </geometry>
      <origin rpy="0 0 0" xyz="0 0 0.045"/>
    </collision>
    <inertial>
      <origin xyz="0 0 0.045" rpy="0 0 0"/>
      <mass value="1.0"/>
      <inertia ixx="0.002" ixy="0.0" ixz="0.0" iyy="0.001" iyz="0.0" izz="0.003"/>
    </inertial>
  </link>

  <!-- Left Wheel -->
  <link name="lwheel">
    <visual>
      <geometry>
        <cylinder length="0.008" radius="0.026"/>
      </geometry>
      <origin rpy="0 0 0" xyz="0 0 0"/>
      <material name="black">
        <color rgba="0 0 0 1"/>
      </material>
    </visual>
    <collision>
      <geometry>
        <cylinder length="0.008" radius="0.026"/>
      </geometry>
      <origin rpy="0 0 0" xyz="0 0 0"/>
    </collision>
    <inertial>
      <origin xyz="0 0 0" rpy="0 0 0"/>
      <mass value="0.2"/>
      <inertia ixx="0.00005" ixy="0.0" ixz="0.0" iyy="0.00005" iyz="0.0" izz="0.0001"/>
    </inertial>
  </link>

  <!-- Rotational Joint for Left Wheel -->
  <joint name="base_to_lwheel" type="continuous">
    <parent link="base_link"/>
    <child link="lwheel"/>
    <origin xyz="0.035 0.045 0.026" rpy="1.5708 0 0"/>
    <axis xyz="0 0 1"/> <!-- Rotate around Z-axis -->
  </joint>

  <!-- Right Wheel -->
  <link name="rwheel">
    <visual>
      <geometry>
        <cylinder length="0.008" radius="0.026"/>
      </geometry>
      <origin rpy="0 0 0" xyz="0 0 0"/>
      <material name="black">
        <color rgba="0 0 0 1"/>
      </material>
    </visual>
    <collision>
      <geometry>
        <cylinder length="0.008" radius="0.026"/>
      </geometry>
      <origin rpy="0 0 0" xyz="0 0 0"/>
    </collision>
    <inertial>
      <origin xyz="0 0 0" rpy="0 0 0"/>
      <mass value="0.2"/>
      <inertia ixx="0.00005" ixy="0.0" ixz="0.0" iyy="0.00005" iyz="0.0" izz="0.0001"/>
    </inertial>
  </link>

  <!-- Rotational Joint for Right Wheel -->
  <joint name="base_to_rwheel" type="continuous">
    <parent link="base_link"/>
    <child link="rwheel"/>
    <origin xyz="0.035 -0.045 0.026" rpy="1.5708 0 0"/>
    <axis xyz="0 0 1"/> <!-- Rotate around Z-axis -->
  </joint>


  <!-- Left Wheel -->
  <link name="lwheel_back">
    <visual>
      <geometry>
        <cylinder length="0.008" radius="0.026"/>
      </geometry>
      <origin rpy="0 0 0" xyz="0 0 0"/>
      <material name="black">
        <color rgba="0 0 0 1"/>
      </material>
    </visual>
    <collision>
      <geometry>
        <cylinder length="0.008" radius="0.026"/>
      </geometry>
      <origin rpy="0 0 0" xyz="0 0 0"/>
    </collision>
    <inertial>
      <origin xyz="0 0 0" rpy="0 0 0"/>
      <mass value="0.2"/>
      <inertia ixx="0.00005" ixy="0.0" ixz="0.0" iyy="0.00005" iyz="0.0" izz="0.0001"/>
    </inertial>
  </link>

  <!-- Rotational Joint for Left Wheel -->
  <joint name="base_to_lwheel_back" type="continuous">
    <axis xyz="0 0 1"/> 
    <parent link="base_link"/>
    <child link="lwheel_back"/>
    <origin xyz="-0.035 0.045 0.026" rpy="1.5708 0 0"/>
    <!-- <limit lower="-3.1415" upper="3.1415" effort="1e2" velocity="0.2"/> -->

  </joint>

  <!-- Right Wheel -->
  <link name="rwheel_back">
    <visual>
      <geometry>
        <cylinder length="0.008" radius="0.026"/>
      </geometry>
      <origin rpy="0 0 0" xyz="0 0 0"/>
      <material name="black">
        <color rgba="0 0 0 1"/>
      </material>
    </visual>
    <collision>
      <geometry>
        <cylinder length="0.008" radius="0.026"/>
      </geometry>
      <origin rpy="0 0 0" xyz="0 0 0"/>
    </collision>
    <inertial>
      <origin xyz="0 0 0" rpy="0 0 0"/>
      <mass value="0.2"/>
      <inertia ixx="0.00005" ixy="0.0" ixz="0.0" iyy="0.00005" iyz="0.0" izz="0.0001"/>
    </inertial>
  </link>

  <!-- Rotational Joint for Right Wheel -->
  <joint name="base_to_rwheel_back" type="continuous">
    <parent link="base_link"/>
    <child link="rwheel_back"/>
    <origin xyz="-0.0350 -0.045 0.026" rpy="1.5708 0 0"/>
    <!-- <limit lower="-3.1415" upper="3.1415" effort="1e2" velocity="0.2"/> -->
    <axis xyz="0 0 1"/> 
  </joint>


  <!-- Front Wheel Attachment -->
  <link name="shovel">
    <visual>
      <geometry>
        <box size="0.01 0.1 0.05"/>
      </geometry>
      <origin rpy="0 0 0" xyz="0 0 0"/>
      <material name="blue">
        <color rgba="0 0 0.8 1"/>
      </material>
    </visual>
    <collision>
      <geometry>
        <box size="0.01 0.1 0.05"/>
      </geometry>
      <origin rpy="0 0 0" xyz="0 0 0"/>
    </collision>
    <inertial>
      <origin xyz="0 0 0" rpy="0 0 0"/>
      <mass value="0.3"/>
      <inertia ixx="0.0001" ixy="0.0" ixz="0.0" iyy="0.0001" iyz="0.0" izz="0.0002"/>
    </inertial>
  </link>

  <joint name="base_to_fattach" type="fixed">
    <parent link="base_link"/>
    <child link="shovel"/>
    <origin xyz="0.08 0 0.025" rpy="0 0 0"/>
  </joint>

</robot>
